File: Risk_Level.csv
Bridge_ID,Age (years),Length (m),Width (m),Height (m),Traffic_Volume (vehicles/day),Weather_Conditions,Water_Flow_Rate (mÂ³/s),Stress (MPa),Strain (%),Tensile_Strength (MPa),Rainfall (mm),Bridge_Design,Humidity (%),Risk_Level
1,26,50,5,10,100,Rainy,0,0,0,200,0,Arch,0,Low
2,47,50.1950195,5.00450045,10.0090009,100.990099,Sunny,0.500050005,0.010001,0.0010001,200.080008,0.050005001,Beam,0.010001,Low
31,2,55.85058506,5.135013501,10.270027,129.7029703,Rainy,15.00150015,0.300030003,0.030003,202.40024,1.500150015,Arch,0.300030003,Low
60,18,61.50615062,5.265526553,10.53105311,158.4158416,Windy,29.5029503,0.590059006,0.059005901,204.720472,2.95029503,Truss,0.590059006,Low
89,14,67.16171617,5.396039604,10.79207921,187.1287129,Cloudy,44.00440044,0.880088009,0.088008801,207.0407041,4.400440044,Beam,0.880088009,Low
118,24,72.81728173,5.526552655,11.05310531,215.8415842,Snowy,58.50585059,1.170117012,0.117011701,209.3609361,5.850585059,Arch,1.170117012,Low
147,45,78.47284728,5.657065707,11.31413141,244.5544554,Sunny,73.00730073,1.460146015,0.146014601,211.6811681,7.300730073,Truss,1.460146015,Low
176,3,84.12841284,5.787578758,11.57515752,273.2673267,Rainy,87.50875088,1.750175018,0.175017502,214.0014001,8.750875088,Beam,1.750175018,Low
205,16,89.7839784,5.918091809,11.83618362,301.980198,Windy,102.010201,2.04020402,0.204020402,216.3216322,10.2010201,Arch,2.04020402,Low
234,2,95.43954395,6.04860486,12.09720972,330.6930693,Cloudy,116.5116512,2.330233023,0.233023302,218.6418642,11.65116512,Truss,2.330233023,Low
263,2,101.0951095,6.179117912,12.35823582,359.4059406,Snowy,131.0131013,2.620262026,0.262026203,220.9620962,13.10131013,Beam,2.620262026,Low
292,14,106.7506751,6.309630963,12.61926193,388.1188119,Sunny,145.5145515,2.910291029,0.291029103,223.2823282,14.55145515,Arch,2.910291029,Low
321,16,112.4062406,6.440144014,12.88028803,416.8316832,Rainy,160.0160016,3.200320032,0.320032003,225.6025603,16.00160016,Truss,3.200320032,Low
350,20,118.0618062,6.570657066,13.14131413,445.5445545,Windy,174.5174517,3.490349035,0.349034903,227.9227923,17.45174517,Beam,3.490349035,Low
379,1,123.7173717,6.701170117,13.40234023,474.2574257,Cloudy,189.0189019,3.780378038,0.378037804,230.2430243,18.90189019,Arch,3.780378038,Low
408,47,129.3729373,6.831683168,13.66336634,502.970297,Snowy,203.520352,4.070407041,0.407040704,232.5632563,20.3520352,Truss,4.070407041,Low
437,32,135.0285029,6.96219622,13.92439244,531.6831683,Sunny,218.0218022,4.360436044,0.436043604,234.8834883,21.80218022,Beam,4.360436044,Low
466,34,140.6840684,7.092709271,14.18541854,560.3960396,Rainy,232.5232523,4.650465047,0.465046505,237.2037204,23.25232523,Arch,4.650465047,Low
495,48,146.339634,7.223222322,14.44644464,589.1089109,Windy,247.0247025,4.940494049,0.494049405,239.5239524,24.70247025,Truss,4.940494049,Low
524,36,151.9951995,7.353735374,14.70747075,617.8217822,Cloudy,261.5261526,5.230523052,0.523052305,241.8441844,26.15261526,Beam,5.230523052,Low
553,11,157.6507651,7.484248425,14.96849685,646.5346535,Snowy,276.0276028,5.520552055,0.552055206,244.1644164,27.60276028,Arch,5.520552055,Low
582,36,163.3063306,7.614761476,15.22952295,675.2475248,Sunny,290.5290529,5.810581058,0.581058106,246.4846485,29.05290529,Truss,5.810581058,Low
611,12,168.9618962,7.745274527,15.49054905,703.960396,Rainy,305.0305031,6.100610061,0.610061006,248.8048805,30.50305031,Beam,6.100610061,Low
640,46,174.6174617,7.875787579,15.75157516,732.6732673,Windy,319.5319532,6.390639064,0.639063906,251.1251125,31.95319532,Arch,6.390639064,Low
669,8,180.2730273,8.00630063,16.01260126,761.3861386,Cloudy,334.0334033,6.680668067,0.668066807,253.4453445,33.40334033,Truss,6.680668067,Low
698,40,185.9285929,8.136813681,16.27362736,790.0990099,Snowy,348.5348535,6.97069707,0.697069707,255.7655766,34.85348535,Beam,6.97069707,Low
727,26,191.5841584,8.267326733,16.53465347,818.8118812,Sunny,363.0363036,7.260726073,0.726072607,258.0858086,36.30363036,Arch,7.260726073,Low
756,47,197.239724,8.397839784,16.79567957,847.5247525,Rainy,377.5377538,7.550755076,0.755075508,260.4060406,37.75377538,Truss,7.550755076,Low
785,36,202.8952895,8.528352835,17.05670567,876.2376238,Windy,392.0392039,7.840784078,0.784078408,262.7262726,39.20392039,Beam,7.840784078,Low
814,24,208.5508551,8.658865887,17.31773177,904.950495,Cloudy,406.5406541,8.130813081,0.813081308,265.0465047,40.65406541,Arch,8.130813081,Low
843,36,214.2064206,8.789378938,17.57875788,933.6633663,Snowy,421.0421042,8.420842084,0.842084208,267.3667367,42.10421042,Truss,8.420842084,Low
872,1,219.8619862,8.919891989,17.83978398,962.3762376,Sunny,435.5435544,8.710871087,0.871087109,269.6869687,43.55435544,Beam,8.710871087,Low
901,6,225.5175518,9.050405041,18.10081008,991.0891089,Rainy,450.0450045,9.00090009,0.900090009,272.0072007,45.00450045,Arch,9.00090009,Low
930,14,231.1731173,9.180918092,18.36183618,1019.80198,Windy,464.5464546,9.290929093,0.929092909,274.3274327,46.45464546,Truss,9.290929093,Low
959,33,236.8286829,9.311431143,18.62286229,1048.514851,Cloudy,479.0479048,9.580958096,0.95809581,276.6476648,47.90479048,Beam,9.580958096,Low
988,41,242.4842484,9.441944194,18.88388839,1077.227723,Snowy,493.5493549,9.870987099,0.98709871,278.9678968,49.35493549,Arch,9.870987099,Low
1017,16,248.139814,9.572457246,19.14491449,1105.940594,Sunny,508.0508051,10.1610161,1.01610161,281.2881288,50.80508051,Truss,10.1610161,Low
1046,9,253.7953795,9.702970297,19.40594059,1134.653465,Rainy,522.5522552,10.4510451,1.04510451,283.6083608,52.25522552,Beam,10.4510451,Low
1075,0,259.4509451,9.833483348,19.6669667,1163.366337,Windy,537.0537054,10.74107411,1.074107411,285.9285929,53.70537054,Arch,10.74107411,Low
1104,41,265.1065107,9.9639964,19.9279928,1192.079208,Cloudy,551.5551555,11.03110311,1.103110311,288.2488249,55.15551555,Truss,11.03110311,Moderate
1133,15,270.7620762,10.09450945,20.1890189,1220.792079,Snowy,566.0566057,11.32113211,1.132113211,290.5690569,56.60566057,Beam,11.32113211,Low
1162,48,276.4176418,10.2250225,20.450045,1249.50495,Sunny,580.5580558,11.61116112,1.161116112,292.8892889,58.05580558,Arch,11.61116112,Moderate
1191,4,282.0732073,10.35553555,20.71107111,1278.217822,Rainy,595.059506,11.90119012,1.190119012,295.209521,59.5059506,Truss,11.90119012,Low
1220,33,287.7287729,10.4860486,20.97209721,1306.930693,Windy,609.5609561,12.19121912,1.219121912,297.529753,60.95609561,Beam,12.19121912,Moderate
1249,32,293.3843384,10.61656166,21.23312331,1335.643564,Cloudy,624.0624062,12.48124812,1.248124812,299.849985,62.40624062,Arch,12.48124812,Moderate
1278,29,299.039904,10.74707471,21.49414941,1364.356436,Snowy,638.5638564,12.77127713,1.277127713,302.170217,63.85638564,Truss,12.77127713,Low
1307,4,304.6954695,10.87758776,21.75517552,1393.069307,Sunny,653.0653065,13.06130613,1.306130613,304.490449,65.30653065,Beam,13.06130613,Low
1336,37,310.3510351,11.00810081,22.01620162,1421.782178,Rainy,667.5667567,13.35133513,1.335133513,306.8106811,66.75667567,Arch,13.35133513,Moderate
1365,18,316.0066007,11.13861386,22.27722772,1450.49505,Windy,682.0682068,13.64136414,1.364136414,309.1309131,68.20682068,Truss,13.64136414,Low
1394,19,321.6621662,11.26912691,22.53825383,1479.207921,Cloudy,696.569657,13.93139314,1.393139314,311.4511451,69.6569657,Beam,13.93139314,Low
1423,7,327.3177318,11.39963996,22.79927993,1507.920792,Snowy,711.0711071,14.22142214,1.422142214,313.7713771,71.10711071,Arch,14.22142214,Low
1452,7,332.9732973,11.53015302,23.06030603,1536.633663,Sunny,725.5725573,14.51145115,1.451145115,316.0916092,72.55725573,Truss,14.51145115,Low
1481,6,338.6288629,11.66066607,23.32133213,1565.346535,Rainy,740.0740074,14.80148015,1.480148015,318.4118412,74.00740074,Beam,14.80148015,Low
1510,41,344.2844284,11.79117912,23.58235824,1594.059406,Windy,754.5754575,15.09150915,1.509150915,320.7320732,75.45754575,Arch,15.09150915,Moderate
1539,16,349.939994,11.92169217,23.84338434,1622.772277,Cloudy,769.0769077,15.38153815,1.538153815,323.0523052,76.90769077,Truss,15.38153815,Low
1568,2,355.5955596,12.05220522,24.10441044,1651.485149,Snowy,783.5783578,15.67156716,1.567156716,325.3725373,78.35783578,Beam,15.67156716,Low
1597,33,361.2511251,12.18271827,24.36543654,1680.19802,Sunny,798.079808,15.96159616,1.596159616,327.6927693,79.8079808,Arch,15.96159616,Moderate
1626,12,366.9066907,12.31323132,24.62646265,1708.910891,Rainy,812.5812581,16.25162516,1.625162516,330.0130013,81.25812581,Truss,16.25162516,Low
1655,28,372.5622562,12.44374437,24.88748875,1737.623762,Windy,827.0827083,16.54165417,1.654165417,332.3332333,82.70827083,Beam,16.54165417,Moderate
1684,15,378.2178218,12.57425743,25.14851485,1766.336634,Cloudy,841.5841584,16.83168317,1.683168317,334.6534653,84.15841584,Arch,16.83168317,Moderate
1713,20,383.8733873,12.70477048,25.40954095,1795.049505,Snowy,856.0856086,17.12171217,1.712171217,336.9736974,85.60856086,Truss,17.12171217,Moderate
1742,12,389.5289529,12.83528353,25.67056706,1823.762376,Sunny,870.5870587,17.41174117,1.741174117,339.2939294,87.05870587,Beam,17.41174117,Moderate
1771,31,395.1845185,12.96579658,25.93159316,1852.475248,Rainy,885.0885089,17.70177018,1.770177018,341.6141614,88.50885089,Arch,17.70177018,Moderate
1800,8,400.840084,13.09630963,26.19261926,1881.188119,Windy,899.589959,17.99179918,1.799179918,343.9343934,89.9589959,Truss,17.99179918,Low
1829,46,406.4956496,13.22682268,26.45364536,1909.90099,Cloudy,914.0914091,18.28182818,1.828182818,346.2546255,91.40914091,Beam,18.28182818,Moderate
1858,35,412.1512151,13.35733573,26.71467147,1938.613861,Snowy,928.5928593,18.57185719,1.857185719,348.5748575,92.85928593,Arch,18.57185719,Moderate
1887,0,417.8067807,13.48784878,26.97569757,1967.326733,Sunny,943.0943094,18.86188619,1.886188619,350.8950895,94.30943094,Truss,18.86188619,Low
1916,45,423.4623462,13.61836184,27.23672367,1996.039604,Rainy,957.5957596,19.15191519,1.915191519,353.2153215,95.75957596,Beam,19.15191519,Moderate
1945,8,429.1179118,13.74887489,27.49774977,2024.752475,Windy,972.0972097,19.44194419,1.944194419,355.5355536,97.20972097,Arch,19.44194419,Moderate
1974,13,434.7734773,13.87938794,27.75877588,2053.465347,Cloudy,986.5986599,19.7319732,1.97319732,357.8557856,98.65986599,Truss,19.7319732,Moderate
2003,25,440.4290429,14.00990099,28.01980198,2082.178218,Snowy,1001.10011,20.0220022,2.00220022,360.1760176,100.110011,Beam,20.0220022,Moderate
2032,5,446.0846085,14.14041404,28.28082808,2110.891089,Sunny,1015.60156,20.3120312,2.03120312,362.4962496,101.560156,Arch,20.3120312,Moderate
2061,11,451.740174,14.27092709,28.54185419,2139.60396,Rainy,1030.10301,20.60206021,2.060206021,364.8164816,103.010301,Truss,20.60206021,Moderate
2090,7,457.3957396,14.40144014,28.80288029,2168.316832,Windy,1044.60446,20.89208921,2.089208921,367.1367137,104.460446,Beam,20.89208921,Moderate
2119,7,463.0513051,14.5319532,29.06390639,2197.029703,Cloudy,1059.105911,21.18211821,2.118211821,369.4569457,105.9105911,Arch,21.18211821,Moderate
2148,46,468.7068707,14.66246625,29.32493249,2225.742574,Snowy,1073.607361,21.47214721,2.147214721,371.7771777,107.3607361,Truss,21.47214721,Moderate
2177,5,474.3624362,14.7929793,29.5859586,2254.455446,Sunny,1088.108811,21.76217622,2.176217622,374.0974097,108.8108811,Beam,21.76217622,Moderate
2206,14,480.0180018,14.92349235,29.8469847,2283.168317,Rainy,1102.610261,22.05220522,2.205220522,376.4176418,110.2610261,Arch,22.05220522,Moderate
2235,27,485.6735674,15.0540054,30.1080108,2311.881188,Windy,1117.111711,22.34223422,2.234223422,378.7378738,111.7111711,Truss,22.34223422,Moderate
2264,1,491.3291329,15.18451845,30.3690369,2340.594059,Cloudy,1131.613161,22.63226323,2.263226323,381.0581058,113.1613161,Beam,22.63226323,Moderate
2293,3,496.9846985,15.3150315,30.63006301,2369.306931,Snowy,1146.114611,22.92229223,2.292229223,383.3783378,114.6114611,Arch,22.92229223,Moderate
2322,47,502.640264,15.44554455,30.89108911,2398.019802,Sunny,1160.616062,23.21232123,2.321232123,385.6985699,116.0616062,Truss,23.21232123,Moderate
2351,38,508.2958296,15.57605761,31.15211521,2426.732673,Rainy,1175.117512,23.50235024,2.350235024,388.0188019,117.5117512,Beam,23.50235024,Moderate
2380,13,513.9513951,15.70657066,31.41314131,2455.445545,Windy,1189.618962,23.79237924,2.379237924,390.3390339,118.9618962,Arch,23.79237924,Moderate
2409,25,519.6069607,15.83708371,31.67416742,2484.158416,Cloudy,1204.120412,24.08240824,2.408240824,392.6592659,120.4120412,Truss,24.08240824,Moderate
2438,15,525.2625263,15.96759676,31.93519352,2512.871287,Snowy,1218.621862,24.37243724,2.437243724,394.9794979,121.8621862,Beam,24.37243724,Moderate
2467,3,530.9180918,16.09810981,32.19621962,2541.584158,Sunny,1233.123312,24.66246625,2.466246625,397.29973,123.3123312,Arch,24.66246625,Moderate
2496,16,536.5736574,16.22862286,32.45724572,2570.29703,Rainy,1247.624762,24.95249525,2.495249525,399.619962,124.7624762,Truss,24.95249525,Moderate
2525,37,542.2292229,16.35913591,32.71827183,2599.009901,Windy,1262.126213,25.24252425,2.524252425,401.940194,126.2126213,Beam,25.24252425,Moderate
2554,0,547.8847885,16.48964896,32.97929793,2627.722772,Cloudy,1276.627663,25.53255326,2.553255326,404.260426,127.6627663,Arch,25.53255326,Moderate
2583,43,553.540354,16.62016202,33.24032403,2656.435644,Snowy,1291.129113,25.82258226,2.582258226,406.5806581,129.1129113,Truss,25.82258226,Moderate
2612,28,559.1959196,16.75067507,33.50135014,2685.148515,Sunny,1305.630563,26.11261126,2.611261126,408.9008901,130.5630563,Beam,26.11261126,Moderate
2641,33,564.8514851,16.88118812,33.76237624,2713.861386,Rainy,1320.132013,26.40264026,2.640264026,411.2211221,132.0132013,Arch,26.40264026,Moderate
2670,45,570.5070507,17.01170117,34.02340234,2742.574257,Windy,1334.633463,26.69266927,2.669266927,413.5413541,133.4633463,Truss,26.69266927,Moderate
2699,13,576.1626163,17.14221422,34.28442844,2771.287129,Cloudy,1349.134913,26.98269827,2.698269827,415.8615862,134.9134913,Beam,26.98269827,Moderate
2728,34,581.8181818,17.27272727,34.54545455,2800,Snowy,1363.636364,27.27272727,2.727272727,418.1818182,136.3636364,Arch,27.27272727,Moderate
2757,29,587.4737474,17.40324032,34.80648065,2828.712871,Sunny,1378.137814,27.56275628,2.756275628,420.5020502,137.8137814,Truss,27.56275628,Moderate
2786,45,593.1293129,17.53375338,35.06750675,2857.425743,Rainy,1392.639264,27.85278528,2.785278528,422.8222822,139.2639264,Beam,27.85278528,Moderate
2815,18,598.7848785,17.66426643,35.32853285,2886.138614,Windy,1407.140714,28.14281428,2.814281428,425.1425143,140.7140714,Arch,28.14281428,Moderate
2844,27,604.440444,17.79477948,35.58955896,2914.851485,Cloudy,1421.642164,28.43284328,2.843284328,427.4627463,142.1642164,Truss,28.43284328,Moderate
2873,11,610.0960096,17.92529253,35.85058506,2943.564356,Snowy,1436.143614,28.72287229,2.872287229,429.7829783,143.6143614,Beam,28.72287229,Moderate
2902,26,615.7515752,18.05580558,36.11161116,2972.277228,Sunny,1450.645065,29.01290129,2.901290129,432.1032103,145.0645065,Arch,29.01290129,Moderate
2931,6,621.4071407,18.18631863,36.37263726,3000.990099,Rainy,1465.146515,29.30293029,2.930293029,434.4234423,146.5146515,Truss,29.30293029,Moderate
2960,44,627.0627063,18.31683168,36.63366337,3029.70297,Windy,1479.647965,29.5929593,2.95929593,436.7436744,147.9647965,Beam,29.5929593,Moderate
2989,22,632.7182718,18.44734473,36.89468947,3058.415842,Cloudy,1494.149415,29.8829883,2.98829883,439.0639064,149.4149415,Arch,29.8829883,Moderate
3018,48,638.3738374,18.57785779,37.15571557,3087.128713,Snowy,1508.650865,30.1730173,3.01730173,441.3841384,150.8650865,Truss,30.1730173,Moderate
3047,18,644.0294029,18.70837084,37.41674167,3115.841584,Sunny,1523.152315,30.4630463,3.04630463,443.7043704,152.3152315,Beam,30.4630463,Moderate
3076,37,649.6849685,18.83888389,37.67776778,3144.554455,Rainy,1537.653765,30.75307531,3.075307531,446.0246025,153.7653765,Arch,30.75307531,Moderate
3105,0,655.3405341,18.96939694,37.93879388,3173.267327,Windy,1552.155216,31.04310431,3.104310431,448.3448345,155.2155216,Truss,31.04310431,Moderate
3134,14,660.9960996,19.09990999,38.19981998,3201.980198,Cloudy,1566.656666,31.33313331,3.133313331,450.6650665,156.6656666,Beam,31.33313331,Moderate
3163,33,666.6516652,19.23042304,38.46084608,3230.693069,Snowy,1581.158116,31.62316232,3.162316232,452.9852985,158.1158116,Arch,31.62316232,Moderate
3192,22,672.3072307,19.36093609,38.72187219,3259.405941,Sunny,1595.659566,31.91319132,3.191319132,455.3055306,159.5659566,Truss,31.91319132,Moderate
3221,11,677.9627963,19.49144914,38.98289829,3288.118812,Rainy,1610.161016,32.20322032,3.220322032,457.6257626,161.0161016,Beam,32.20322032,Moderate
3250,33,683.6183618,19.6219622,39.24392439,3316.831683,Windy,1624.662466,32.49324932,3.249324932,459.9459946,162.4662466,Arch,32.49324932,Moderate
3279,14,689.2739274,19.75247525,39.5049505,3345.544554,Cloudy,1639.163916,32.78327833,3.278327833,462.2662266,163.9163916,Truss,32.78327833,Moderate
3308,12,694.9294929,19.8829883,39.7659766,3374.257426,Snowy,1653.665367,33.07330733,3.307330733,464.5864586,165.3665367,Beam,33.07330733,Moderate
3337,49,700.5850585,20.01350135,40.0270027,3402.970297,Sunny,1668.166817,33.36333633,3.336333633,466.9066907,166.8166817,Arch,33.36333633,Moderate
3366,15,706.2406241,20.1440144,40.2880288,3431.683168,Rainy,1682.668267,33.65336534,3.365336534,469.2269227,168.2668267,Truss,33.65336534,Moderate
3395,14,711.8961896,20.27452745,40.54905491,3460.39604,Windy,1697.169717,33.94339434,3.394339434,471.5471547,169.7169717,Beam,33.94339434,Moderate
3424,12,717.5517552,20.4050405,40.81008101,3489.108911,Cloudy,1711.671167,34.23342334,3.423342334,473.8673867,171.1671167,Arch,34.23342334,Moderate
3453,34,723.2073207,20.53555356,41.07110711,3517.821782,Snowy,1726.172617,34.52345235,3.452345235,476.1876188,172.6172617,Truss,34.52345235,Moderate
3482,42,728.8628863,20.66606661,41.33213321,3546.534653,Sunny,1740.674067,34.81348135,3.481348135,478.5078508,174.0674067,Beam,34.81348135,Moderate
3511,18,734.5184518,20.79657966,41.59315932,3575.247525,Rainy,1755.175518,35.10351035,3.510351035,480.8280828,175.5175518,Arch,35.10351035,Moderate
3540,16,740.1740174,20.92709271,41.85418542,3603.960396,Windy,1769.676968,35.39353935,3.539353935,483.1483148,176.9676968,Truss,35.39353935,Moderate
3569,24,745.829583,21.05760576,42.11521152,3632.673267,Cloudy,1784.178418,35.68356836,3.568356836,485.4685469,178.4178418,Beam,35.68356836,Moderate
3598,33,751.4851485,21.18811881,42.37623762,3661.386139,Snowy,1798.679868,35.97359736,3.597359736,487.7887789,179.8679868,Arch,35.97359736,Moderate
3627,5,757.1407141,21.31863186,42.63726373,3690.09901,Sunny,1813.181318,36.26362636,3.626362636,490.1090109,181.3181318,Truss,36.26362636,Moderate
3656,43,762.7962796,21.44914491,42.89828983,3718.811881,Rainy,1827.682768,36.55365537,3.655365537,492.4292429,182.7682768,Beam,36.55365537,Moderate
3685,25,768.4518452,21.57965797,43.15931593,3747.524752,Windy,1842.184218,36.84368437,3.684368437,494.7494749,184.2184218,Arch,36.84368437,Moderate
3714,40,774.1074107,21.71017102,43.42034203,3776.237624,Cloudy,1856.685669,37.13371337,3.713371337,497.069707,185.6685669,Truss,37.13371337,Moderate
3743,33,779.7629763,21.84068407,43.68136814,3804.950495,Snowy,1871.187119,37.42374237,3.742374237,499.389939,187.1187119,Beam,37.42374237,Moderate
3772,0,785.4185419,21.97119712,43.94239424,3833.663366,Sunny,1885.688569,37.71377138,3.771377138,501.710171,188.5688569,Arch,37.71377138,Moderate
3801,39,791.0741074,22.10171017,44.20342034,3862.376238,Rainy,1900.190019,38.00380038,3.800380038,504.030403,190.0190019,Truss,38.00380038,Moderate
3830,37,796.729673,22.23222322,44.46444644,3891.089109,Windy,1914.691469,38.29382938,3.829382938,506.3506351,191.4691469,Beam,38.29382938,Moderate
3859,3,802.3852385,22.36273627,44.72547255,3919.80198,Cloudy,1929.192919,38.58385839,3.858385839,508.6708671,192.9192919,Arch,38.58385839,Moderate
3888,6,808.0408041,22.49324932,44.98649865,3948.514851,Snowy,1943.694369,38.87388739,3.887388739,510.9910991,194.3694369,Truss,38.87388739,Moderate
3917,16,813.6963696,22.62376238,45.24752475,3977.227723,Sunny,1958.19582,39.16391639,3.916391639,513.3113311,195.819582,Beam,39.16391639,Moderate
3946,31,819.3519352,22.75427543,45.50855086,4005.940594,Rainy,1972.69727,39.45394539,3.945394539,515.6315632,197.269727,Arch,39.45394539,Moderate
3975,8,825.0075008,22.88478848,45.76957696,4034.653465,Windy,1987.19872,39.7439744,3.97439744,517.9517952,198.719872,Truss,39.7439744,Moderate
4004,25,830.6630663,23.01530153,46.03060306,4063.366337,Cloudy,2001.70017,40.0340034,4.00340034,520.2720272,200.170017,Beam,40.0340034,Moderate
4033,36,836.3186319,23.14581458,46.29162916,4092.079208,Snowy,2016.20162,40.3240324,4.03240324,522.5922592,201.620162,Arch,40.3240324,Moderate
4062,13,841.9741974,23.27632763,46.55265527,4120.792079,Sunny,2030.70307,40.61406141,4.061406141,524.9124912,203.070307,Truss,40.61406141,Moderate
4091,20,847.629763,23.40684068,46.81368137,4149.50495,Rainy,2045.20452,40.90409041,4.090409041,527.2327233,204.520452,Beam,40.90409041,Moderate
4120,49,853.2853285,23.53735374,47.07470747,4178.217822,Windy,2059.705971,41.19411941,4.119411941,529.5529553,205.9705971,Arch,41.19411941,High
4149,29,858.9408941,23.66786679,47.33573357,4206.930693,Cloudy,2074.207421,41.48414841,4.148414841,531.8731873,207.4207421,Truss,41.48414841,Moderate
4178,43,864.5964596,23.79837984,47.59675968,4235.643564,Snowy,2088.708871,41.77417742,4.177417742,534.1934193,208.8708871,Beam,41.77417742,High
4207,13,870.2520252,23.92889289,47.85778578,4264.356436,Sunny,2103.210321,42.06420642,4.206420642,536.5136514,210.3210321,Arch,42.06420642,Moderate
4236,20,875.9075908,24.05940594,48.11881188,4293.069307,Rainy,2117.711771,42.35423542,4.235423542,538.8338834,211.7711771,Truss,42.35423542,Moderate
4265,20,881.5631563,24.18991899,48.37983798,4321.782178,Windy,2132.213221,42.64426443,4.264426443,541.1541154,213.2213221,Beam,42.64426443,Moderate
4294,37,887.2187219,24.32043204,48.64086409,4350.49505,Cloudy,2146.714671,42.93429343,4.293429343,543.4743474,214.6714671,Arch,42.93429343,Moderate
4323,48,892.8742874,24.45094509,48.90189019,4379.207921,Snowy,2161.216122,43.22432243,4.322432243,545.7945795,216.1216122,Truss,43.22432243,High
4352,35,898.529853,24.58145815,49.16291629,4407.920792,Sunny,2175.717572,43.51435144,4.351435144,548.1148115,217.5717572,Beam,43.51435144,High
4381,14,904.1854185,24.7119712,49.42394239,4436.633663,Rainy,2190.219022,43.80438044,4.380438044,550.4350435,219.0219022,Arch,43.80438044,Moderate
4410,29,909.8409841,24.84248425,49.6849685,4465.346535,Windy,2204.720472,44.09440944,4.409440944,552.7552755,220.4720472,Truss,44.09440944,Moderate
4439,16,915.4965497,24.9729973,49.9459946,4494.059406,Cloudy,2219.221922,44.38443844,4.438443844,555.0755076,221.9221922,Beam,44.38443844,Moderate
4468,19,921.1521152,25.10351035,50.2070207,4522.772277,Snowy,2233.723372,44.67446745,4.467446745,557.3957396,223.3723372,Arch,44.67446745,Moderate
4497,27,926.8076808,25.2340234,50.4680468,4551.485149,Sunny,2248.224822,44.96449645,4.496449645,559.7159716,224.8224822,Truss,44.96449645,Moderate
4526,19,932.4632463,25.36453645,50.72907291,4580.19802,Rainy,2262.726273,45.25452545,4.525452545,562.0362036,226.2726273,Beam,45.25452545,Moderate
4555,19,938.1188119,25.4950495,50.99009901,4608.910891,Windy,2277.227723,45.54455446,4.554455446,564.3564356,227.7227723,Arch,45.54455446,Moderate
4584,11,943.7743774,25.62556256,51.25112511,4637.623762,Cloudy,2291.729173,45.83458346,4.583458346,566.6766677,229.1729173,Truss,45.83458346,Moderate
4613,45,949.429943,25.75607561,51.51215122,4666.336634,Snowy,2306.230623,46.12461246,4.612461246,568.9968997,230.6230623,Beam,46.12461246,High
4642,33,955.0855086,25.88658866,51.77317732,4695.049505,Sunny,2320.732073,46.41464146,4.641464146,571.3171317,232.0732073,Arch,46.41464146,High
4671,34,960.7410741,26.01710171,52.03420342,4723.762376,Rainy,2335.233523,46.70467047,4.670467047,573.6373637,233.5233523,Truss,46.70467047,High
4700,2,966.3966397,26.14761476,52.29522952,4752.475248,Windy,2349.734973,46.99469947,4.699469947,575.9575958,234.9734973,Beam,46.99469947,Moderate
4729,35,972.0522052,26.27812781,52.55625563,4781.188119,Cloudy,2364.236424,47.28472847,4.728472847,578.2778278,236.4236424,Arch,47.28472847,High
4758,17,977.7077708,26.40864086,52.81728173,4809.90099,Snowy,2378.737874,47.57475748,4.757475748,580.5980598,237.8737874,Truss,47.57475748,Moderate
4787,36,983.3633363,26.53915392,53.07830783,4838.613861,Sunny,2393.239324,47.86478648,4.786478648,582.9182918,239.3239324,Beam,47.86478648,High
4816,3,989.0189019,26.66966697,53.33933393,4867.326733,Rainy,2407.740774,48.15481548,4.815481548,585.2385239,240.7740774,Arch,48.15481548,Moderate
4845,1,994.6744674,26.80018002,53.60036004,4896.039604,Windy,2422.242224,48.44484448,4.844484448,587.5587559,242.2242224,Truss,48.44484448,Moderate
4874,15,1000.330033,26.93069307,53.86138614,4924.752475,Cloudy,2436.743674,48.73487349,4.873487349,589.8789879,243.6743674,Beam,48.73487349,High
4903,1,1005.985599,27.06120612,54.12241224,4953.465347,Snowy,2451.245125,49.02490249,4.902490249,592.1992199,245.1245125,Arch,49.02490249,Moderate
4932,39,1011.641164,27.19171917,54.38343834,4982.178218,Sunny,2465.746575,49.31493149,4.931493149,594.5194519,246.5746575,Truss,49.31493149,High
4961,17,1017.29673,27.32223222,54.64446445,5010.891089,Rainy,2480.248025,49.6049605,4.96049605,596.839684,248.0248025,Beam,49.6049605,High
4990,26,1022.952295,27.45274527,54.90549055,5039.60396,Windy,2494.749475,49.8949895,4.98949895,599.159916,249.4749475,Arch,49.8949895,High
5019,36,1028.607861,27.58325833,55.16651665,5068.316832,Cloudy,2509.250925,50.1850185,5.01850185,601.480148,250.9250925,Truss,50.1850185,High
5048,20,1034.263426,27.71377138,55.42754275,5097.029703,Snowy,2523.752375,50.4750475,5.04750475,603.80038,252.3752375,Beam,50.4750475,High
5077,26,1039.918992,27.84428443,55.68856886,5125.742574,Sunny,2538.253825,50.76507651,5.076507651,606.1206121,253.8253825,Arch,50.76507651,High
5106,38,1045.574557,27.97479748,55.94959496,5154.455446,Rainy,2552.755276,51.05510551,5.105510551,608.4408441,255.2755276,Truss,51.05510551,High
5135,3,1051.230123,28.10531053,56.21062106,5183.168317,Windy,2567.256726,51.34513451,5.134513451,610.7610761,256.7256726,Beam,51.34513451,High
5164,41,1056.885689,28.23582358,56.47164716,5211.881188,Cloudy,2581.758176,51.63516352,5.163516352,613.0813081,258.1758176,Arch,51.63516352,High
5193,39,1062.541254,28.36633663,56.73267327,5240.594059,Snowy,2596.259626,51.92519252,5.192519252,615.4015402,259.6259626,Truss,51.92519252,High
5222,7,1068.19682,28.49684968,56.99369937,5269.306931,Sunny,2610.761076,52.21522152,5.221522152,617.7217722,261.0761076,Beam,52.21522152,High
5251,38,1073.852385,28.62736274,57.25472547,5298.019802,Rainy,2625.262526,52.50525053,5.250525053,620.0420042,262.5262526,Arch,52.50525053,High
5280,32,1079.507951,28.75787579,57.51575158,5326.732673,Windy,2639.763976,52.79527953,5.279527953,622.3622362,263.9763976,Truss,52.79527953,High
5309,45,1085.163516,28.88838884,57.77677768,5355.445545,Cloudy,2654.265427,53.08530853,5.308530853,624.6824682,265.4265427,Beam,53.08530853,High
5338,34,1090.819082,29.01890189,58.03780378,5384.158416,Snowy,2668.766877,53.37533753,5.337533753,627.0027003,266.8766877,Arch,53.37533753,High
5367,45,1096.474647,29.14941494,58.29882988,5412.871287,Sunny,2683.268327,53.66536654,5.366536654,629.3229323,268.3268327,Truss,53.66536654,High
5396,32,1102.130213,29.27992799,58.55985599,5441.584158,Rainy,2697.769777,53.95539554,5.395539554,631.6431643,269.7769777,Beam,53.95539554,High
5425,3,1107.785779,29.41044104,58.82088209,5470.29703,Windy,2712.271227,54.24542454,5.424542454,633.9633963,271.2271227,Arch,54.24542454,High
5454,43,1113.441344,29.5409541,59.08190819,5499.009901,Cloudy,2726.772677,54.53545355,5.453545355,636.2836284,272.6772677,Truss,54.53545355,High
5483,15,1119.09691,29.67146715,59.34293429,5527.722772,Snowy,2741.274127,54.82548255,5.482548255,638.6038604,274.1274127,Beam,54.82548255,High
5512,26,1124.752475,29.8019802,59.6039604,5556.435644,Sunny,2755.775578,55.11551155,5.511551155,640.9240924,275.5775578,Arch,55.11551155,High
5541,18,1130.408041,29.93249325,59.8649865,5585.148515,Rainy,2770.277028,55.40554055,5.540554055,643.2443244,277.0277028,Truss,55.40554055,High
5570,35,1136.063606,30.0630063,60.1260126,5613.861386,Windy,2784.778478,55.69556956,5.569556956,645.5645565,278.4778478,Beam,55.69556956,High
5599,35,1141.719172,30.19351935,60.3870387,5642.574257,Cloudy,2799.279928,55.98559856,5.598559856,647.8847885,279.9279928,Arch,55.98559856,High
5628,22,1147.374737,30.3240324,60.64806481,5671.287129,Snowy,2813.781378,56.27562756,5.627562756,650.2050205,281.3781378,Truss,56.27562756,High
5657,35,1153.030303,30.45454545,60.90909091,5700,Sunny,2828.282828,56.56565657,5.656565657,652.5252525,282.8282828,Beam,56.56565657,High
5686,14,1158.685869,30.58505851,61.17011701,5728.712871,Rainy,2842.784278,56.85568557,5.685568557,654.8454845,284.2784278,Arch,56.85568557,High
5715,33,1164.341434,30.71557156,61.43114311,5757.425743,Windy,2857.285729,57.14571457,5.714571457,657.1657166,285.7285729,Truss,57.14571457,High
5744,9,1169.997,30.84608461,61.69216922,5786.138614,Cloudy,2871.787179,57.43574357,5.743574357,659.4859486,287.1787179,Beam,57.43574357,High
5773,0,1175.652565,30.97659766,61.95319532,5814.851485,Snowy,2886.288629,57.72577258,5.772577258,661.8061806,288.6288629,Arch,57.72577258,High
5802,8,1181.308131,31.10711071,62.21422142,5843.564356,Sunny,2900.790079,58.01580158,5.801580158,664.1264126,290.0790079,Truss,58.01580158,High
5831,34,1186.963696,31.23762376,62.47524752,5872.277228,Rainy,2915.291529,58.30583058,5.830583058,666.4466447,291.5291529,Beam,58.30583058,High
5860,47,1192.619262,31.36813681,62.73627363,5900.990099,Windy,2929.792979,58.59585959,5.859585959,668.7668767,292.9792979,Arch,58.59585959,High
5889,15,1198.274827,31.49864986,62.99729973,5929.70297,Cloudy,2944.294429,58.88588859,5.888588859,671.0871087,294.4294429,Truss,58.88588859,High
5918,1,1203.930393,31.62916292,63.25832583,5958.415842,Snowy,2958.79588,59.17591759,5.917591759,673.4073407,295.879588,Beam,59.17591759,High
5947,3,1209.585959,31.75967597,63.51935194,5987.128713,Sunny,2973.29733,59.46594659,5.946594659,675.7275728,297.329733,Arch,59.46594659,High
5976,43,1215.241524,31.89018902,63.78037804,6015.841584,Rainy,2987.79878,59.7559756,5.97559756,678.0478048,298.779878,Truss,59.7559756,High
6005,43,1220.89709,32.02070207,64.04140414,6044.554455,Windy,3002.30023,60.0460046,6.00460046,680.3680368,300.230023,Beam,60.0460046,High
6034,7,1226.552655,32.15121512,64.30243024,6073.267327,Cloudy,3016.80168,60.3360336,6.03360336,682.6882688,301.680168,Arch,60.3360336,High
6063,43,1232.208221,32.28172817,64.56345635,6101.980198,Snowy,3031.30313,60.62606261,6.062606261,685.0085009,303.130313,Truss,60.62606261,High
6092,24,1237.863786,32.41224122,64.82448245,6130.693069,Sunny,3045.80458,60.91609161,6.091609161,687.3287329,304.580458,Beam,60.91609161,High
6121,34,1243.519352,32.54275428,65.08550855,6159.405941,Rainy,3060.306031,61.20612061,6.120612061,689.6489649,306.0306031,Arch,61.20612061,High
6150,1,1249.174917,32.67326733,65.34653465,6188.118812,Windy,3074.807481,61.49614961,6.149614961,691.9691969,307.4807481,Truss,61.49614961,High
6179,31,1254.830483,32.80378038,65.60756076,6216.831683,Cloudy,3089.308931,61.78617862,6.178617862,694.2894289,308.9308931,Beam,61.78617862,High
6208,18,1260.486049,32.93429343,65.86858686,6245.544554,Snowy,3103.810381,62.07620762,6.207620762,696.609661,310.3810381,Arch,62.07620762,High
6237,36,1266.141614,33.06480648,66.12961296,6274.257426,Sunny,3118.311831,62.36623662,6.236623662,698.929893,311.8311831,Truss,62.36623662,High
6266,33,1271.79718,33.19531953,66.39063906,6302.970297,Rainy,3132.813281,62.65626563,6.265626563,701.250125,313.2813281,Beam,62.65626563,High
6295,23,1277.452745,33.32583258,66.65166517,6331.683168,Windy,3147.314731,62.94629463,6.294629463,703.570357,314.7314731,Arch,62.94629463,High
6324,2,1283.108311,33.45634563,66.91269127,6360.39604,Cloudy,3161.816182,63.23632363,6.323632363,705.8905891,316.1816182,Truss,63.23632363,High
6353,14,1288.763876,33.58685869,67.17371737,6389.108911,Snowy,3176.317632,63.52635264,6.352635264,708.2108211,317.6317632,Beam,63.52635264,High
6382,3,1294.419442,33.71737174,67.43474347,6417.821782,Sunny,3190.819082,63.81638164,6.381638164,710.5310531,319.0819082,Arch,63.81638164,High
6411,47,1300.075008,33.84788479,67.69576958,6446.534653,Rainy,3205.320532,64.10641064,6.410641064,712.8512851,320.5320532,Truss,64.10641064,High
6440,24,1305.730573,33.97839784,67.95679568,6475.247525,Windy,3219.821982,64.39643964,6.439643964,715.1715172,321.9821982,Beam,64.39643964,High
6469,39,1311.386139,34.10891089,68.21782178,6503.960396,Cloudy,3234.323432,64.68646865,6.468646865,717.4917492,323.4323432,Arch,64.68646865,High
6498,49,1317.041704,34.23942394,68.47884788,6532.673267,Snowy,3248.824882,64.97649765,6.497649765,719.8119812,324.8824882,Truss,64.97649765,High
6527,9,1322.69727,34.36993699,68.73987399,6561.386139,Sunny,3263.326333,65.26652665,6.526652665,722.1322132,326.3326333,Beam,65.26652665,High
6556,41,1328.352835,34.50045005,69.00090009,6590.09901,Rainy,3277.827783,65.55655566,6.555655566,724.4524452,327.7827783,Arch,65.55655566,High
6585,33,1334.008401,34.6309631,69.26192619,6618.811881,Windy,3292.329233,65.84658466,6.584658466,726.7726773,329.2329233,Truss,65.84658466,High
6614,44,1339.663966,34.76147615,69.5229523,6647.524752,Cloudy,3306.830683,66.13661366,6.613661366,729.0929093,330.6830683,Beam,66.13661366,High
6643,29,1345.319532,34.8919892,69.7839784,6676.237624,Snowy,3321.332133,66.42664266,6.642664266,731.4131413,332.1332133,Arch,66.42664266,High
6672,39,1350.975098,35.02250225,70.0450045,6704.950495,Sunny,3335.833583,66.71667167,6.671667167,733.7333733,333.5833583,Truss,66.71667167,High
6701,19,1356.630663,35.1530153,70.3060306,6733.663366,Rainy,3350.335034,67.00670067,6.700670067,736.0536054,335.0335034,Beam,67.00670067,High
6730,42,1362.286229,35.28352835,70.56705671,6762.376238,Windy,3364.836484,67.29672967,6.729672967,738.3738374,336.4836484,Arch,67.29672967,High
6759,28,1367.941794,35.4140414,70.82808281,6791.089109,Cloudy,3379.337934,67.58675868,6.758675868,740.6940694,337.9337934,Truss,67.58675868,High
6788,35,1373.59736,35.54455446,71.08910891,6819.80198,Snowy,3393.839384,67.87678768,6.787678768,743.0143014,339.3839384,Beam,67.87678768,High
6817,14,1379.252925,35.67506751,71.35013501,6848.514851,Sunny,3408.340834,68.16681668,6.816681668,745.3345335,340.8340834,Arch,68.16681668,High
6846,44,1384.908491,35.80558056,71.61116112,6877.227723,Rainy,3422.842284,68.45684568,6.845684568,747.6547655,342.2842284,Truss,68.45684568,High
6875,6,1390.564056,35.93609361,71.87218722,6905.940594,Windy,3437.343734,68.74687469,6.874687469,749.9749975,343.7343734,Beam,68.74687469,High
6904,24,1396.219622,36.06660666,72.13321332,6934.653465,Cloudy,3451.845185,69.03690369,6.903690369,752.2952295,345.1845185,Arch,69.03690369,High
6933,36,1401.875188,36.19711971,72.39423942,6963.366337,Snowy,3466.346635,69.32693269,6.932693269,754.6154615,346.6346635,Truss,69.32693269,High
6962,5,1407.530753,36.32763276,72.65526553,6992.079208,Sunny,3480.848085,69.6169617,6.96169617,756.9356936,348.0848085,Beam,69.6169617,High
6991,7,1413.186319,36.45814581,72.91629163,7020.792079,Rainy,3495.349535,69.9069907,6.99069907,759.2559256,349.5349535,Arch,69.9069907,High
7020,18,1418.841884,36.58865887,73.17731773,7049.50495,Windy,3509.850985,70.1970197,7.01970197,761.5761576,350.9850985,Truss,70.1970197,High
7049,6,1424.49745,36.71917192,73.43834383,7078.217822,Cloudy,3524.352435,70.4870487,7.04870487,763.8963896,352.4352435,Beam,70.4870487,High
7078,28,1430.153015,36.84968497,73.69936994,7106.930693,Snowy,3538.853885,70.77707771,7.077707771,766.2166217,353.8853885,Arch,70.77707771,High
7107,36,1435.808581,36.98019802,73.96039604,7135.643564,Sunny,3553.355336,71.06710671,7.106710671,768.5368537,355.3355336,Truss,71.06710671,High
7136,37,1441.464146,37.11071107,74.22142214,7164.356436,Rainy,3567.856786,71.35713571,7.135713571,770.8570857,356.7856786,Beam,71.35713571,High
7165,9,1447.119712,37.24122412,74.48244824,7193.069307,Windy,3582.358236,71.64716472,7.164716472,773.1773177,358.2358236,Arch,71.64716472,High
7194,47,1452.775278,37.37173717,74.74347435,7221.782178,Cloudy,3596.859686,71.93719372,7.193719372,775.4975498,359.6859686,Truss,71.93719372,High
7223,41,1458.430843,37.50225023,75.00450045,7250.49505,Snowy,3611.361136,72.22722272,7.222722272,777.8177818,361.1361136,Beam,72.22722272,High
7252,25,1464.086409,37.63276328,75.26552655,7279.207921,Sunny,3625.862586,72.51725173,7.251725173,780.1380138,362.5862586,Arch,72.51725173,High
7281,9,1469.741974,37.76327633,75.52655266,7307.920792,Rainy,3640.364036,72.80728073,7.280728073,782.4582458,364.0364036,Truss,72.80728073,High
7310,44,1475.39754,37.89378938,75.78757876,7336.633663,Windy,3654.865487,73.09730973,7.309730973,784.7784778,365.4865487,Beam,73.09730973,High
7339,48,1481.053105,38.02430243,76.04860486,7365.346535,Cloudy,3669.366937,73.38733873,7.338733873,787.0987099,366.9366937,Arch,73.38733873,High
7368,41,1486.708671,38.15481548,76.30963096,7394.059406,Snowy,3683.868387,73.67736774,7.367736774,789.4189419,368.3868387,Truss,73.67736774,High
7397,2,1492.364236,38.28532853,76.57065707,7422.772277,Sunny,3698.369837,73.96739674,7.396739674,791.7391739,369.8369837,Beam,73.96739674,High
7426,39,1498.019802,38.41584158,76.83168317,7451.485149,Rainy,3712.871287,74.25742574,7.425742574,794.0594059,371.2871287,Arch,74.25742574,High
7455,6,1503.675368,38.54635464,77.09270927,7480.19802,Windy,3727.372737,74.54745475,7.454745475,796.379638,372.7372737,Truss,74.54745475,High
7484,2,1509.330933,38.67686769,77.35373537,7508.910891,Cloudy,3741.874187,74.83748375,7.483748375,798.69987,374.1874187,Beam,74.83748375,High
7513,20,1514.986499,38.80738074,77.61476148,7537.623762,Snowy,3756.375638,75.12751275,7.512751275,801.020102,375.6375638,Arch,75.12751275,High
7542,44,1520.642064,38.93789379,77.87578758,7566.336634,Sunny,3770.877088,75.41754175,7.541754175,803.340334,377.0877088,Truss,75.41754175,High
7571,25,1526.29763,39.06840684,78.13681368,7595.049505,Rainy,3785.378538,75.70757076,7.570757076,805.6605661,378.5378538,Beam,75.70757076,High
7600,39,1531.953195,39.19891989,78.39783978,7623.762376,Windy,3799.879988,75.99759976,7.599759976,807.9807981,379.9879988,Arch,75.99759976,High
7629,13,1537.608761,39.32943294,78.65886589,7652.475248,Cloudy,3814.381438,76.28762876,7.628762876,810.3010301,381.4381438,Truss,76.28762876,High
7658,1,1543.264326,39.45994599,78.91989199,7681.188119,Snowy,3828.882888,76.57765777,7.657765777,812.6212621,382.8882888,Beam,76.57765777,High
7687,33,1548.919892,39.59045905,79.18091809,7709.90099,Sunny,3843.384338,76.86768677,7.686768677,814.9414941,384.3384338,Arch,76.86768677,High
7716,43,1554.575458,39.7209721,79.44194419,7738.613861,Rainy,3857.885789,77.15771577,7.715771577,817.2617262,385.7885789,Truss,77.15771577,High
7745,22,1560.231023,39.85148515,79.7029703,7767.326733,Windy,3872.387239,77.44774477,7.744774477,819.5819582,387.2387239,Beam,77.44774477,High
7774,11,1565.886589,39.9819982,79.9639964,7796.039604,Cloudy,3886.888689,77.73777378,7.773777378,821.9021902,388.6888689,Arch,77.73777378,High
7803,21,1571.542154,40.11251125,80.2250225,7824.752475,Snowy,3901.390139,78.02780278,7.802780278,824.2224222,390.1390139,Truss,78.02780278,High
7832,18,1577.19772,40.2430243,80.4860486,7853.465347,Sunny,3915.891589,78.31783178,7.831783178,826.5426543,391.5891589,Beam,78.31783178,High
7861,18,1582.853285,40.37353735,80.74707471,7882.178218,Rainy,3930.393039,78.60786079,7.860786079,828.8628863,393.0393039,Arch,78.60786079,High
7890,26,1588.508851,40.50405041,81.00810081,7910.891089,Windy,3944.894489,78.89788979,7.889788979,831.1831183,394.4894489,Truss,78.89788979,High
7919,45,1594.164416,40.63456346,81.26912691,7939.60396,Cloudy,3959.39594,79.18791879,7.918791879,833.5033503,395.939594,Beam,79.18791879,High
7948,33,1599.819982,40.76507651,81.53015302,7968.316832,Snowy,3973.89739,79.47794779,7.947794779,835.8235824,397.389739,Arch,79.47794779,High
7977,34,1605.475548,40.89558956,81.79117912,7997.029703,Sunny,3988.39884,79.7679768,7.97679768,838.1438144,398.839884,Truss,79.7679768,High
8006,8,1611.131113,41.02610261,82.05220522,8025.742574,Rainy,4002.90029,80.0580058,8.00580058,840.4640464,400.290029,Beam,80.0580058,High
8035,35,1616.786679,41.15661566,82.31323132,8054.455446,Windy,4017.40174,80.3480348,8.03480348,842.7842784,401.740174,Arch,80.3480348,High
8064,47,1622.442244,41.28712871,82.57425743,8083.168317,Cloudy,4031.90319,80.63806381,8.063806381,845.1045105,403.190319,Truss,80.63806381,High
8093,15,1628.09781,41.41764176,82.83528353,8111.881188,Snowy,4046.40464,80.92809281,8.092809281,847.4247425,404.640464,Beam,80.92809281,High
8122,44,1633.753375,41.54815482,83.09630963,8140.594059,Sunny,4060.906091,81.21812181,8.121812181,849.7449745,406.0906091,Arch,81.21812181,High
8151,45,1639.408941,41.67866787,83.35733573,8169.306931,Rainy,4075.407541,81.50815082,8.150815082,852.0652065,407.5407541,Truss,81.50815082,High
8180,2,1645.064506,41.80918092,83.61836184,8198.019802,Windy,4089.908991,81.79817982,8.179817982,854.3854385,408.9908991,Beam,81.79817982,High
8209,33,1650.720072,41.93969397,83.87938794,8226.732673,Cloudy,4104.410441,82.08820882,8.208820882,856.7056706,410.4410441,Arch,82.08820882,High
8238,14,1656.375638,42.07020702,84.14041404,8255.445545,Snowy,4118.911891,82.37823782,8.237823782,859.0259026,411.8911891,Truss,82.37823782,High
8267,22,1662.031203,42.20072007,84.40144014,8284.158416,Sunny,4133.413341,82.66826683,8.266826683,861.3461346,413.3413341,Beam,82.66826683,High
8296,36,1667.686769,42.33123312,84.66246625,8312.871287,Rainy,4147.914791,82.95829583,8.295829583,863.6663666,414.7914791,Arch,82.95829583,High
8325,46,1673.342334,42.46174617,84.92349235,8341.584158,Windy,4162.416242,83.24832483,8.324832483,865.9865987,416.2416242,Truss,83.24832483,High
8354,1,1678.9979,42.59225923,85.18451845,8370.29703,Cloudy,4176.917692,83.53835384,8.353835384,868.3068307,417.6917692,Beam,83.53835384,High
8383,48,1684.653465,42.72277228,85.44554455,8399.009901,Snowy,4191.419142,83.82838284,8.382838284,870.6270627,419.1419142,Arch,83.82838284,High
8412,9,1690.309031,42.85328533,85.70657066,8427.722772,Sunny,4205.920592,84.11841184,8.411841184,872.9472947,420.5920592,Truss,84.11841184,High
8441,29,1695.964596,42.98379838,85.96759676,8456.435644,Rainy,4220.422042,84.40844084,8.440844084,875.2675268,422.0422042,Beam,84.40844084,High
8470,27,1701.620162,43.11431143,86.22862286,8485.148515,Windy,4234.923492,84.69846985,8.469846985,877.5877588,423.4923492,Arch,84.69846985,High
8499,8,1707.275728,43.24482448,86.48964896,8513.861386,Cloudy,4249.424942,84.98849885,8.498849885,879.9079908,424.9424942,Truss,84.98849885,High
8528,35,1712.931293,43.37533753,86.75067507,8542.574257,Snowy,4263.926393,85.27852785,8.527852785,882.2282228,426.3926393,Beam,85.27852785,High
8557,20,1718.586859,43.50585059,87.01170117,8571.287129,Sunny,4278.427843,85.56855686,8.556855686,884.5484548,427.8427843,Arch,85.56855686,High
8586,47,1724.242424,43.63636364,87.27272727,8600,Rainy,4292.929293,85.85858586,8.585858586,886.8686869,429.2929293,Truss,85.85858586,High
8615,11,1729.89799,43.76687669,87.53375338,8628.712871,Windy,4307.430743,86.14861486,8.614861486,889.1889189,430.7430743,Beam,86.14861486,High
8644,15,1735.553555,43.89738974,87.79477948,8657.425743,Cloudy,4321.932193,86.43864386,8.643864386,891.5091509,432.1932193,Arch,86.43864386,High
8673,47,1741.209121,44.02790279,88.05580558,8686.138614,Snowy,4336.433643,86.72867287,8.672867287,893.8293829,433.6433643,Truss,86.72867287,High
8702,6,1746.864686,44.15841584,88.31683168,8714.851485,Sunny,4350.935094,87.01870187,8.701870187,896.149615,435.0935094,Beam,87.01870187,High
8731,27,1752.520252,44.28892889,88.57785779,8743.564356,Rainy,4365.436544,87.30873087,8.730873087,898.469847,436.5436544,Arch,87.30873087,High
8760,32,1758.175818,44.41944194,88.83888389,8772.277228,Windy,4379.937994,87.59875988,8.759875988,900.790079,437.9937994,Truss,87.59875988,High
8789,44,1763.831383,44.549955,89.09990999,8800.990099,Cloudy,4394.439444,87.88878888,8.788878888,903.110311,439.4439444,Beam,87.88878888,High
8818,5,1769.486949,44.68046805,89.36093609,8829.70297,Snowy,4408.940894,88.17881788,8.817881788,905.4305431,440.8940894,Arch,88.17881788,High
8847,8,1775.142514,44.8109811,89.6219622,8858.415842,Sunny,4423.442344,88.46884688,8.846884688,907.7507751,442.3442344,Truss,88.46884688,High
8876,3,1780.79808,44.94149415,89.8829883,8887.128713,Rainy,4437.943794,88.75887589,8.875887589,910.0710071,443.7943794,Beam,88.75887589,High
8905,20,1786.453645,45.0720072,90.1440144,8915.841584,Windy,4452.445245,89.04890489,8.904890489,912.3912391,445.2445245,Arch,89.04890489,High
8934,24,1792.109211,45.20252025,90.4050405,8944.554455,Cloudy,4466.946695,89.33893389,8.933893389,914.7114711,446.6946695,Truss,89.33893389,High
8963,6,1797.764776,45.3330333,90.66606661,8973.267327,Snowy,4481.448145,89.6289629,8.96289629,917.0317032,448.1448145,Beam,89.6289629,High
8992,9,1803.420342,45.46354635,90.92709271,9001.980198,Sunny,4495.949595,89.9189919,8.99189919,919.3519352,449.5949595,Arch,89.9189919,High
9021,20,1809.075908,45.59405941,91.18811881,9030.693069,Rainy,4510.451045,90.2090209,9.02090209,921.6721672,451.0451045,Truss,90.2090209,High
9050,5,1814.731473,45.72457246,91.44914491,9059.405941,Windy,4524.952495,90.4990499,9.04990499,923.9923992,452.4952495,Beam,90.4990499,High
9079,15,1820.387039,45.85508551,91.71017102,9088.118812,Cloudy,4539.453945,90.78907891,9.078907891,926.3126313,453.9453945,Arch,90.78907891,High
9108,4,1826.042604,45.98559856,91.97119712,9116.831683,Snowy,4553.955396,91.07910791,9.107910791,928.6328633,455.3955396,Truss,91.07910791,High
9137,49,1831.69817,46.11611161,92.23222322,9145.544554,Sunny,4568.456846,91.36913691,9.136913691,930.9530953,456.8456846,Beam,91.36913691,High
9166,26,1837.353735,46.24662466,92.49324932,9174.257426,Rainy,4582.958296,91.65916592,9.165916592,933.2733273,458.2958296,Arch,91.65916592,High
9195,25,1843.009301,46.37713771,92.75427543,9202.970297,Windy,4597.459746,91.94919492,9.194919492,935.5935594,459.7459746,Truss,91.94919492,High
9224,41,1848.664866,46.50765077,93.01530153,9231.683168,Cloudy,4611.961196,92.23922392,9.223922392,937.9137914,461.1961196,Beam,92.23922392,High
9253,22,1854.320432,46.63816382,93.27632763,9260.39604,Snowy,4626.462646,92.52925293,9.252925293,940.2340234,462.6462646,Arch,92.52925293,High
9282,42,1859.975998,46.76867687,93.53735374,9289.108911,Sunny,4640.964096,92.81928193,9.281928193,942.5542554,464.0964096,Truss,92.81928193,High
9311,48,1865.631563,46.89918992,93.79837984,9317.821782,Rainy,4655.465547,93.10931093,9.310931093,944.8744874,465.5465547,Beam,93.10931093,High
9340,42,1871.287129,47.02970297,94.05940594,9346.534653,Windy,4669.966997,93.39933993,9.339933993,947.1947195,466.9966997,Arch,93.39933993,High
9369,35,1876.942694,47.16021602,94.32043204,9375.247525,Cloudy,4684.468447,93.68936894,9.368936894,949.5149515,468.4468447,Truss,93.68936894,High
9398,48,1882.59826,47.29072907,94.58145815,9403.960396,Snowy,4698.969897,93.97939794,9.397939794,951.8351835,469.8969897,Beam,93.97939794,High
9427,11,1888.253825,47.42124212,94.84248425,9432.673267,Sunny,4713.471347,94.26942694,9.426942694,954.1554155,471.3471347,Arch,94.26942694,High
9456,33,1893.909391,47.55175518,95.10351035,9461.386139,Rainy,4727.972797,94.55945595,9.455945595,956.4756476,472.7972797,Truss,94.55945595,High
9485,19,1899.564956,47.68226823,95.36453645,9490.09901,Windy,4742.474247,94.84948495,9.484948495,958.7958796,474.2474247,Beam,94.84948495,High
9514,7,1905.220522,47.81278128,95.62556256,9518.811881,Cloudy,4756.975698,95.13951395,9.513951395,961.1161116,475.6975698,Arch,95.13951395,High
9543,43,1910.876088,47.94329433,95.88658866,9547.524752,Snowy,4771.477148,95.42954295,9.542954295,963.4363436,477.1477148,Truss,95.42954295,High
9572,8,1916.531653,48.07380738,96.14761476,9576.237624,Sunny,4785.978598,95.71957196,9.571957196,965.7565757,478.5978598,Beam,95.71957196,High
9601,18,1922.187219,48.20432043,96.40864086,9604.950495,Rainy,4800.480048,96.00960096,9.600960096,968.0768077,480.0480048,Arch,96.00960096,High
9630,48,1927.842784,48.33483348,96.66966697,9633.663366,Windy,4814.981498,96.29962996,9.629962996,970.3970397,481.4981498,Truss,96.29962996,High
9659,16,1933.49835,48.46534653,96.93069307,9662.376238,Cloudy,4829.482948,96.58965897,9.658965897,972.7172717,482.9482948,Beam,96.58965897,High
9688,7,1939.153915,48.59585959,97.19171917,9691.089109,Snowy,4843.984398,96.87968797,9.687968797,975.0375038,484.3984398,Arch,96.87968797,High
9717,44,1944.809481,48.72637264,97.45274527,9719.80198,Sunny,4858.485849,97.16971697,9.716971697,977.3577358,485.8485849,Truss,97.16971697,High
9746,32,1950.465047,48.85688569,97.71377138,9748.514851,Rainy,4872.987299,97.45974597,9.745974597,979.6779678,487.2987299,Beam,97.45974597,High
9775,21,1956.120612,48.98739874,97.97479748,9777.227723,Windy,4887.488749,97.74977498,9.774977498,981.9981998,488.7488749,Arch,97.74977498,High
9804,29,1961.776178,49.11791179,98.23582358,9805.940594,Cloudy,4901.990199,98.03980398,9.803980398,984.3184318,490.1990199,Truss,98.03980398,High
9833,47,1967.431743,49.24842484,98.49684968,9834.653465,Snowy,4916.491649,98.32983298,9.832983298,986.6386639,491.6491649,Beam,98.32983298,High
9862,35,1973.087309,49.37893789,98.75787579,9863.366337,Sunny,4930.993099,98.61986199,9.861986199,988.9588959,493.0993099,Arch,98.61986199,High
9891,29,1978.742874,49.50945095,99.01890189,9892.079208,Rainy,4945.494549,98.90989099,9.890989099,991.2791279,494.5494549,Truss,98.90989099,High
9920,45,1984.39844,49.639964,99.27992799,9920.792079,Windy,4959.996,99.19991999,9.919991999,993.5993599,495.9996,Beam,99.19991999,High
9949,4,1990.054005,49.77047705,99.5409541,9949.50495,Cloudy,4974.49745,99.48994899,9.948994899,995.919592,497.449745,Arch,99.48994899,High
9978,12,1995.709571,49.9009901,99.8019802,9978.217822,Snowy,4988.9989,99.779978,9.9779978,998.239824,498.89989,Truss,99.779978,High
10000,7,2000,50,100,10000,Windy,5000,100,10,1000,500,Arch,100,High